<?xml version="1.0" encoding="utf-8"?><testsuites><testsuite name="pytest" errors="1" failures="0" skipped="0" tests="1" time="1.490" timestamp="2021-11-07T12:58:54.285269" hostname="oleg-ThinkPad-T470s"><testcase classname="pytest" name="internal" time="0.000"><error message="internal error">Traceback (most recent call last):
  File "/usr/local/lib/python3.8/dist-packages/_pytest/main.py", line 269, in wrap_session
    session.exitstatus = doit(config, session) or 0
  File "/usr/local/lib/python3.8/dist-packages/_pytest/main.py", line 323, in _main
    config.hook.pytest_runtestloop(session=session)
  File "/usr/local/lib/python3.8/dist-packages/pluggy/hooks.py", line 286, in __call__
    return self._hookexec(self, self.get_hookimpls(), kwargs)
  File "/usr/local/lib/python3.8/dist-packages/pluggy/manager.py", line 93, in _hookexec
    return self._inner_hookexec(hook, methods, kwargs)
  File "/usr/local/lib/python3.8/dist-packages/pluggy/manager.py", line 84, in &lt;lambda&gt;
    self._inner_hookexec = lambda hook, methods, kwargs: hook.multicall(
  File "/usr/local/lib/python3.8/dist-packages/pluggy/callers.py", line 208, in _multicall
    return outcome.get_result()
  File "/usr/local/lib/python3.8/dist-packages/pluggy/callers.py", line 80, in get_result
    raise ex[1].with_traceback(ex[2])
  File "/usr/local/lib/python3.8/dist-packages/pluggy/callers.py", line 187, in _multicall
    res = hook_impl.function(*args)
  File "/usr/local/lib/python3.8/dist-packages/_pytest/main.py", line 348, in pytest_runtestloop
    item.config.hook.pytest_runtest_protocol(item=item, nextitem=nextitem)
  File "/usr/local/lib/python3.8/dist-packages/pluggy/hooks.py", line 286, in __call__
    return self._hookexec(self, self.get_hookimpls(), kwargs)
  File "/usr/local/lib/python3.8/dist-packages/pluggy/manager.py", line 93, in _hookexec
    return self._inner_hookexec(hook, methods, kwargs)
  File "/usr/local/lib/python3.8/dist-packages/pluggy/manager.py", line 84, in &lt;lambda&gt;
    self._inner_hookexec = lambda hook, methods, kwargs: hook.multicall(
  File "/usr/local/lib/python3.8/dist-packages/pluggy/callers.py", line 208, in _multicall
    return outcome.get_result()
  File "/usr/local/lib/python3.8/dist-packages/pluggy/callers.py", line 80, in get_result
    raise ex[1].with_traceback(ex[2])
  File "/usr/local/lib/python3.8/dist-packages/pluggy/callers.py", line 187, in _multicall
    res = hook_impl.function(*args)
  File "/usr/local/lib/python3.8/dist-packages/_pytest/runner.py", line 109, in pytest_runtest_protocol
    runtestprotocol(item, nextitem=nextitem)
  File "/usr/local/lib/python3.8/dist-packages/_pytest/runner.py", line 120, in runtestprotocol
    rep = call_and_report(item, "setup", log)
  File "/usr/local/lib/python3.8/dist-packages/_pytest/runner.py", line 217, in call_and_report
    report: TestReport = hook.pytest_runtest_makereport(item=item, call=call)
  File "/usr/local/lib/python3.8/dist-packages/pluggy/hooks.py", line 286, in __call__
    return self._hookexec(self, self.get_hookimpls(), kwargs)
  File "/usr/local/lib/python3.8/dist-packages/pluggy/manager.py", line 93, in _hookexec
    return self._inner_hookexec(hook, methods, kwargs)
  File "/usr/local/lib/python3.8/dist-packages/pluggy/manager.py", line 84, in &lt;lambda&gt;
    self._inner_hookexec = lambda hook, methods, kwargs: hook.multicall(
  File "/usr/local/lib/python3.8/dist-packages/pluggy/callers.py", line 203, in _multicall
    gen.send(outcome)
  File "/home/oleg/PycharmProjects1/PythonSelFramework/tests/conftest.py", line 53, in pytest_runtest_makereport
    _capture_screenshot(file_name)
  File "/home/oleg/PycharmProjects1/PythonSelFramework/tests/conftest.py", line 61, in _capture_screenshot
    driver.get_screenshot_as_file(name)
AttributeError: 'NoneType' object has no attribute 'get_screenshot_as_file'</error></testcase></testsuite></testsuites>